<?xml version="1.0" ?>
<!-- =================================================================================== -->
<!-- |    This document was autogenerated by xacro from my_robot.urdf.xacro            | -->
<!-- |    EDITING THIS FILE BY HAND IS NOT RECOMMENDED                                 | -->
<!-- =================================================================================== -->
<robot name="my_robot">
  <material name="blue">
    <color rgba="0 0 0.5 1"/>
  </material>
  <material name="black">
    <color rgba="0 0 0 1"/>
  </material>
  <material name="red">
    <color rgba="1 0 0 1"/>
  </material>
  <material name="grey">
    <color rgba="0.5 0.5 0.5 1"/>
  </material>
  <material name="orange">
    <color rgba="1.0 0.5 0.0 1.0"/>
  </material>
  <material name="yellow">
    <color rgba="1.0 1.0 0.0 1.0"/>
  </material>
  <link name="base_footprint"/>
  <link name="base_link">
    <visual>
      <geometry>
        <box size="2.5 1.5 1"/>
      </geometry>
      <origin rpy="0 0 0" xyz="0 0 0.5"/>
      <material name="red"/>
    </visual>
    <collision>
      <geometry>
        <box size="2.5 1.5 1"/>
      </geometry>
      <origin rpy="0 0 0" xyz="0 0 0.5"/>
    </collision>
    <inertial>
      <origin rpy="0 0 0" xyz="0 0 0.5"/>
      <mass value="5.0"/>
      <inertia ixx="12.083333333333334" ixy="0" ixz="0" iyy="14.166666666666668" iyz="0" izz="5.416666666666667"/>
    </inertial>
  </link>
  <link name="right_front_dif">
    <visual>
      <geometry>
        <cylinder length="0.05" radius="0.02"/>
      </geometry>
      <origin rpy="0 0 0" xyz="0 0 0"/>
      <material name="black"/>
    </visual>
    <collision>
      <geometry>
        <cylinder length="0.05" radius="0.02"/>
      </geometry>
      <origin rpy="0 0 0" xyz="0 0 0"/>
    </collision>
    <inertial>
      <origin rpy="0 0 0" xyz="0 0 0"/>
      <mass value="1"/>
      <inertia ixx="0.0012333333333333332" ixy="0" ixz="0" iyy="0.0012333333333333332" iyz="0" izz="0.0008"/>
    </inertial>
  </link>
  <link name="left_front_dif">
    <visual>
      <geometry>
        <cylinder length="0.05" radius="0.02"/>
      </geometry>
      <origin rpy="0 0 0" xyz="0 0 0"/>
      <material name="black"/>
    </visual>
    <collision>
      <geometry>
        <cylinder length="0.05" radius="0.02"/>
      </geometry>
      <origin rpy="0 0 0" xyz="0 0 0"/>
    </collision>
    <inertial>
      <origin rpy="0 0 0" xyz="0 0 0"/>
      <mass value="1"/>
      <inertia ixx="0.0012333333333333332" ixy="0" ixz="0" iyy="0.0012333333333333332" iyz="0" izz="0.0008"/>
    </inertial>
  </link>
  <link name="right_front_wheel_link">
    <visual>
      <geometry>
        <cylinder length="0.2" radius="0.4"/>
      </geometry>
      <origin rpy="0 0 0" xyz="0 0 0.0"/>
      <material name="black"/>
    </visual>
    <collision>
      <geometry>
        <cylinder length="0.2" radius="0.4"/>
      </geometry>
      <origin rpy="0 0 0" xyz="0 0 0.0"/>
    </collision>
    <inertial>
      <origin rpy="0 0 0" xyz="0 0 0.0"/>
      <mass value="1.0"/>
      <inertia ixx="0.17333333333333337" ixy="0" ixz="0" iyy="0.17333333333333337" iyz="0" izz="0.32000000000000006"/>
    </inertial>
  </link>
  <link name="left_front_wheel_link">
    <visual>
      <geometry>
        <cylinder length="0.2" radius="0.4"/>
      </geometry>
      <origin rpy="0 0 0" xyz="0 0 0.0"/>
      <material name="black"/>
    </visual>
    <collision>
      <geometry>
        <cylinder length="0.2" radius="0.4"/>
      </geometry>
      <origin rpy="0 0 0" xyz="0 0 0.0"/>
    </collision>
    <inertial>
      <origin rpy="0 0 0" xyz="0 0 0.0"/>
      <mass value="1.0"/>
      <inertia ixx="0.17333333333333337" ixy="0" ixz="0" iyy="0.17333333333333337" iyz="0" izz="0.32000000000000006"/>
    </inertial>
  </link>
  <link name="right_back_wheel_link">
    <visual>
      <geometry>
        <cylinder length="0.2" radius="0.4"/>
      </geometry>
      <origin rpy="0 0 0" xyz="0 0 0.1"/>
      <material name="black"/>
    </visual>
    <collision>
      <geometry>
        <cylinder length="0.2" radius="0.4"/>
      </geometry>
      <origin rpy="0 0 0" xyz="0 0 0.1"/>
    </collision>
    <inertial>
      <origin rpy="0 0 0" xyz="0 0 0.1"/>
      <mass value="1.0"/>
      <inertia ixx="0.17333333333333337" ixy="0" ixz="0" iyy="0.17333333333333337" iyz="0" izz="0.32000000000000006"/>
    </inertial>
  </link>
  <link name="left_back_wheel_link">
    <visual>
      <geometry>
        <cylinder length="0.2" radius="0.4"/>
      </geometry>
      <origin rpy="0 0 0" xyz="0 0 -0.1"/>
      <material name="black"/>
    </visual>
    <collision>
      <geometry>
        <cylinder length="0.2" radius="0.4"/>
      </geometry>
      <origin rpy="0 0 0" xyz="0 0 -0.1"/>
    </collision>
    <inertial>
      <origin rpy="0 0 0" xyz="0 0 -0.1"/>
      <mass value="1.0"/>
      <inertia ixx="0.17333333333333337" ixy="0" ixz="0" iyy="0.17333333333333337" iyz="0" izz="0.32000000000000006"/>
    </inertial>
  </link>
  <!-- <link name="steering_wheel_link">
        <visual>
            <geometry>
                <cylinder length="0.05" radius="0.2"/>
            </geometry>
            <material name="grey"/>
        </visual>
        <collision>
            <geometry>
                <cylinder length="0.05" radius="0.2"/>
            </geometry>
        </collision>
        <inertial>
            <mass value="0.5"/>
            <inertia ixx="0.001" ixy="0" ixz="0" iyy="0.001" iyz="0" izz="0.001"/>
        </inertial>
    </link> -->
  <joint name="base_joint" type="fixed">
    <parent link="base_footprint"/>
    <child link="base_link"/>
    <origin rpy="0 0 0" xyz="0 0 0.4"/>
  </joint>
  <joint name="left_front_dif_joint" type="revolute">
    <parent link="base_link"/>
    <child link="left_front_dif"/>
    <origin rpy="1.5707963267948966 0 0" xyz="0.625 0.85 0"/>
    <axis xyz="0 1 0"/>
    <limit effort="100" lower="-1" upper="1" velocity="1"/>
    <dynamics damping="0.0" friction="0.0"/>
  </joint>
  <joint name="right_front_dif_joint" type="revolute">
    <parent link="base_link"/>
    <child link="right_front_dif"/>
    <origin rpy="1.5707963267948966 0 0" xyz="0.625 -0.85 0"/>
    <axis xyz="0 1 0"/>
    <limit effort="100" lower="-1" upper="1" velocity="1"/>
    <dynamics damping="0.0" friction="0.0"/>
  </joint>
  <joint name="left_back_wheel_joint" type="continuous">
    <parent link="base_link"/>
    <child link="left_back_wheel_link"/>
    <origin rpy="1.5707963267948966 0 0" xyz="-0.625 0.75 0"/>
    <axis xyz="0 0 -1"/>
  </joint>
  <joint name="right_back_wheel_joint" type="continuous">
    <parent link="base_link"/>
    <child link="right_back_wheel_link"/>
    <origin rpy="1.5707963267948966 0 0" xyz="-0.625 -0.75 0"/>
    <axis xyz="0 0 -1"/>
  </joint>
  <joint name="left_front_dif_wheel_joint" type="continuous">
    <parent link="left_front_dif"/>
    <child link="left_front_wheel_link"/>
    <origin rpy="0 0 0" xyz="0 0 0"/>
    <axis xyz="0 0 -1"/>
    <dynamics damping="0.0" friction="0.0"/>
    <limit effort="100" velocity="100"/>
  </joint>
  <joint name="right_front_dif_wheel_joint" type="continuous">
    <parent link="right_front_dif"/>
    <child link="right_front_wheel_link"/>
    <origin rpy="0 0 0" xyz="0 0 0"/>
    <axis xyz="0 0 -1"/>
    <dynamics damping="0.0" friction="0.0"/>
    <limit effort="100" velocity="100"/>
  </joint>
  <!-- 
    <joint name="steering_wheel_joint" type="continuous">
        <parent link="base_link" />
        <child link="steering_wheel_link" />
        <origin xyz="0 0 0" rpy="0 0 0" />
        <axis xyz="0 0 1" />
    </joint> -->
  <gazebo reference="base_link">
    <material>Gazebo/Red</material>
  </gazebo>
  <gazebo reference="right_front_dif">
    <material>Gazebo/Green</material>
  </gazebo>
  <gazebo reference="left_front_dif">
    <material>Gazebo/Green</material>
  </gazebo>
  <gazebo reference="right_front_wheel_link">
    <material>Gazebo/Black</material>
  </gazebo>
  <gazebo reference="left_front_wheel_link">
    <material>Gazebo/Black</material>
  </gazebo>
  <gazebo reference="right_back_wheel_link">
    <material>Gazebo/Black</material>
  </gazebo>
  <gazebo reference="left_back_wheel_link">
    <material>Gazebo/Black</material>
  </gazebo>
  <!-- ACKERMANN DRİVE PLUGİN  -->
  <gazebo>
    <plugin filename="libgazebo_ros_ackermann_drive.so" name="gazebo_ros_ackermann_drive">
      <update_rate>100.0</update_rate>
      <!-- wheels -->
      <front_left_joint>left_front_dif_wheel_joint</front_left_joint>
      <front_right_joint>right_front_dif_wheel_joint</front_right_joint>
      <rear_left_joint>left_back_wheel_joint</rear_left_joint>
      <rear_right_joint>right_back_wheel_joint</rear_right_joint>
      <left_steering_joint>left_front_dif_joint</left_steering_joint>
      <right_steering_joint>right_front_dif_joint </right_steering_joint>
      <!-- <steering_wheel_joint>steering_wheel_joint</steering_wheel_joint> -->
      <!-- Max absolute steer angle for tyre in radians-->
      <!-- Any cmd_vel angular z greater than this would be capped -->
      <max_steer>0.6458</max_steer>
      <!-- Max absolute steering angle of steering wheel -->
      <max_steering_angle>7.85</max_steering_angle>
      <!-- Max absolute linear speed in m/s -->
      <max_speed>20</max_speed>
      <!-- PID tuning -->
      <left_steering_pid_gain>1500 0 1</left_steering_pid_gain>
      <left_steering_i_range>0 0</left_steering_i_range>
      <right_steering_pid_gain>1500 0 1</right_steering_pid_gain>
      <right_steering_i_range>0 0</right_steering_i_range>
      <linear_velocity_pid_gain>1000 0 1</linear_velocity_pid_gain>
      <linear_velocity_i_range>0 0</linear_velocity_i_range>
      <!-- output -->
      <publish_odom>true</publish_odom>
      <publish_odom_tf>true</publish_odom_tf>
      <publish_wheel_tf>true</publish_wheel_tf>
      <publish_distance>true</publish_distance>
      <publish_steerangle>true</publish_steerangle>
      <odometry_frame>odom</odometry_frame>
      <robot_base_frame>base_footprint</robot_base_frame>
    </plugin>
  </gazebo>
  <link name="gps_link">
    <visual>
      <geometry>
        <box size="0.1 0.1 0.05"/>
      </geometry>
      <origin rpy="0 0 0" xyz="0 0 0.025"/>
      <material name="grey"/>
    </visual>
    <collision>
      <geometry>
        <box size="0.1 0.1 0.05"/>
      </geometry>
      <origin rpy="0 0 0" xyz="0 0 0.025"/>
    </collision>
    <inertial>
      <origin rpy="0 0 0" xyz="0 0 0.025"/>
      <mass value="0.1"/>
      <inertia ixx="0.00041666666666666675" ixy="0" ixz="0" iyy="0.0006666666666666668" iyz="0" izz="0.00041666666666666675"/>
    </inertial>
  </link>
  <link name="imu_link">
    <visual>
      <geometry>
        <box size="0.1 0.1 0.05"/>
      </geometry>
      <origin rpy="0 0 0" xyz="0 0 -0.025"/>
      <material name="grey"/>
    </visual>
    <collision>
      <geometry>
        <box size="0.1 0.1 0.05"/>
      </geometry>
      <origin rpy="0 0 0" xyz="0 0 -0.025"/>
    </collision>
    <inertial>
      <origin rpy="0 0 0" xyz="0 0 -0.025"/>
      <mass value="0.1"/>
      <inertia ixx="0.00041666666666666675" ixy="0" ixz="0" iyy="0.0006666666666666668" iyz="0" izz="0.00041666666666666675"/>
    </inertial>
  </link>
  <joint name="base_gps_joint" type="fixed">
    <parent link="base_link"/>
    <child link="gps_link"/>
    <origin rpy="0 0 0" xyz="0 0 1"/>
  </joint>
  <joint name="base_imu_joint" type="fixed">
    <parent link="base_link"/>
    <child link="imu_link"/>
    <origin rpy="0 0 0" xyz="0 0 0"/>
  </joint>
  <gazebo reference="gps_link">
    <material>Gazebo/Grey</material>
  </gazebo>
  <gazebo reference="imu_link">
    <material>Gazebo/Grey</material>
  </gazebo>
  <!-- GPS -->
  <gazebo reference="gps_link">
    <sensor name="my_gps" type="gps">
      <!-- ensure the sensor is active (required) -->
      <always_on>true</always_on>
      <update_rate>30</update_rate>
      <plugin filename="libgazebo_ros_gps_sensor.so" name="my_gps_plugin">
        <ros>
          <!-- publish to /gps/data -->
          <namespace>/gps</namespace>
          <remapping>~/out:=data</remapping>
          <remapping>~/vel:=velocity</remapping>
        </ros>
      </plugin>
    </sensor>
  </gazebo>
  <!-- IMU -->
  <gazebo reference="imu_link">
    <sensor name="my_imu" type="imu">
      <!-- ensure the sensor is active (required) -->
      <always_on>true</always_on>
      <update_rate>30</update_rate>
      <plugin filename="libgazebo_ros_imu_sensor.so" name="my_imu_plugin">
        <ros>
          <!-- publish to /imu/data -->
          <namespace>/imu</namespace>
          <remapping>~/out:=data</remapping>
        </ros>
      </plugin>
    </sensor>
  </gazebo>
</robot>
